ðŸ”„ Updating global_trend_summary.csv...
Traceback (most recent call last):
  File "/Users/saayedalam/Documents/data_portfolio/meditation-trend-pulse/automation/update_all_datasets.py", line 103, in <module>
    update_global_trend_dataset()
    ~~~~~~~~~~~~~~~~~~~~~~~~~~~^^
  File "/Users/saayedalam/Documents/data_portfolio/meditation-trend-pulse/automation/update_all_datasets.py", line 75, in update_global_trend_dataset
    df_full = pull_full_weekly_data(KEYWORDS)
  File "/Users/saayedalam/Documents/data_portfolio/meditation-trend-pulse/automation/update_all_datasets.py", line 46, in pull_full_weekly_data
    pytrends.build_payload([kw], timeframe="today 5-y")
    ~~~~~~~~~~~~~~~~~~~~~~^^^^^^^^^^^^^^^^^^^^^^^^^^^^^
  File "/Users/saayedalam/jupyterlab-env/lib/python3.13/site-packages/pytrends/request.py", line 189, in build_payload
    self._tokens()
    ~~~~~~~~~~~~^^
  File "/Users/saayedalam/jupyterlab-env/lib/python3.13/site-packages/pytrends/request.py", line 195, in _tokens
    widget_dicts = self._get_data(
                   ~~~~~~~~~~~~~~^
        url=TrendReq.GENERAL_URL,
        ^^^^^^^^^^^^^^^^^^^^^^^^^
    ...<2 lines>...
        trim_chars=4,
        ^^^^^^^^^^^^^
    )['widgets']
    ^
  File "/Users/saayedalam/jupyterlab-env/lib/python3.13/site-packages/pytrends/request.py", line 159, in _get_data
    raise exceptions.TooManyRequestsError.from_response(response)
pytrends.exceptions.TooManyRequestsError: The request failed: Google returned a response with code 429
